<?xml version="1.0"?>

<robot name="miarobot" xmlns:xacro="http://ros.org/wiki/xacro">
    <xacro:macro name="miarobot_wheel" params="wheel_suffix joint_origin_xyz">
        <link name="wheel_${wheel_suffix}">

            <!-- <visual>
                <geometry>
                    <cylinder length="0.035" radius="0.04"/>
                </geometry>
                <material name="black"/>
            </visual> -->

            <inertial>
                <origin xyz="0 0 0" />
                <mass value="0.2" />
                <inertia  ixx="1.0" ixy="0.0"  ixz="0.0"  iyy="1.0"  iyz="0.0"  izz="1.0" />
            </inertial>

            <collision>
                <geometry>
                <cylinder length="0.035" radius="0.04"/>
                </geometry>
                <surface>
                    <friction>
                        <ode>
                            <mu>0.01</mu>
                        </ode>
                    </friction>
                </surface>
            </collision>

        </link>

        <joint name="${wheel_suffix}" type="continuous">
            <parent link="base_link"/>
            <child link="wheel_${wheel_suffix}"/>
            <origin xyz="${joint_origin_xyz}" rpy="1.5708 0 0"/>
            <axis xyz="0 0 -1"/>
        </joint>

    </xacro:macro>

</robot>