<?xml version="1.0" ?>
<!-- =================================================================================== -->
<!-- |    This document was autogenerated by xacro from /home/omar/catkin_ws/src/miarobot_description/urdf/model.urdf.xacro | -->
<!-- |    EDITING THIS FILE BY HAND IS NOT RECOMMENDED                                 | -->
<!-- =================================================================================== -->
<robot name="miarobot">
  <gazebo>
    <plugin filename="libgazebo_ros_planar_move.so" name="object_controller">
      <commandTopic>cmd_vel</commandTopic>
      <odometryTopic>odom</odometryTopic>
      <odometryFrame>odom</odometryFrame>
      <odometryRate>20.0</odometryRate>
      <robotBaseFrame>base_link</robotBaseFrame>
    </plugin>
  </gazebo>
  <gazebo reference="kinect_camera_link">
    <material>Gazebo/Red</material>
  </gazebo>
  <gazebo reference="wheel_right_back">
    <material>Gazebo/DarkGrey</material>
  </gazebo>
  <gazebo reference="wheel_left_back">
    <material>Gazebo/DarkGrey</material>
  </gazebo>
  <gazebo reference="wheel_right_front">
    <material>Gazebo/DarkGrey</material>
  </gazebo>
  <gazebo reference="wheel_left_front">
    <material>Gazebo/DarkGrey</material>
  </gazebo>
  <gazebo reference="camera_link">
    <material>Gazebo/Red</material>
  </gazebo>
  <gazebo reference="imu_link">
    <material>Gazebo/Green</material>
  </gazebo>
  <!-- camera -->
  <!-- <gazebo reference="camera_link">
    <sensor type="camera" name="camera1">
      <update_rate>30.0</update_rate>
      <camera name="head">
        <horizontal_fov>1.3962634</horizontal_fov>
        <image>
          <width>800</width>
          <height>800</height>
          <format>R8G8B8</format>
        </image>
        <clip>
          <near>0.02</near>
          <far>300</far>
        </clip>
        <noise>
          <type>gaussian</type>
          <mean>0.0</mean>
          <stddev>0.007</stddev>
        </noise>
      </camera>

      <plugin name="camera_controller" filename="libgazebo_ros_camera.so">
        <alwaysOn>true</alwaysOn>
        <updateRate>0.0</updateRate>
        <cameraName>miarobot/camera1</cameraName>
        <imageTopicName>image_raw</imageTopicName>
        <cameraInfoTopicName>camera_info</cameraInfoTopicName>
        <frameName>camera_link</frameName>
        <hackBaseline>0.07</hackBaseline>
        <distortionK1>0.0</distortionK1>
        <distortionK2>0.0</distortionK2>
        <distortionK3>0.0</distortionK3>
        <distortionT1>0.0</distortionT1>
        <distortionT2>0.0</distortionT2>
      </plugin>
    </sensor>
  </gazebo> -->
  <!-- Kinect Camera -->
  <gazebo reference="kinect_camera_link">
    <sensor name="kinect_camera_link_camera" type="depth">
      <update_rate>20</update_rate>
      <camera>
        <!-- Default FOV -->
        <!-- <horizontal_fov>1.047198</horizontal_fov> -->
        <!-- 85 degrees -->
        <horizontal_fov>1.48353</horizontal_fov>
        <!-- 90 degrees -->
        <!-- <horizontal_fov>1.5708</horizontal_fov>        -->
        <!-- 120 degrees -->
        <!-- <horizontal_fov>2.1045</horizontal_fov>        -->
        <image>
          <width>640</width>
          <height>480</height>
          <format>B8G8R8</format>
        </image>
        <clip>
          <near>0.05</near>
          <far>15</far>
        </clip>
      </camera>
      <plugin filename="libgazebo_ros_openni_kinect.so" name="kinect_camera_link_controller">
        <baseline>0.2</baseline>
        <alwaysOn>true</alwaysOn>
        <updateRate>30.0</updateRate>
        <cameraName>kinect_camera_ir</cameraName>
        <imageTopicName>/camera/rgb/image_raw</imageTopicName>
        <cameraInfoTopicName>/camera/rgb/camera_info</cameraInfoTopicName>
        <depthImageTopicName>/camera/depth/image_raw</depthImageTopicName>
        <depthImageInfoTopicName>/camera/depth/camera_info</depthImageInfoTopicName>
        <pointCloudTopicName>/camera/depth/points</pointCloudTopicName>
        <frameName>camera_link</frameName>
        <pointCloudCutoff>0.5</pointCloudCutoff>
        <pointCloudCutoffMax>10.0</pointCloudCutoffMax>
        <distortionK1>0.00000001</distortionK1>
        <distortionK2>0.00000001</distortionK2>
        <distortionK3>0.00000001</distortionK3>
        <distortionT1>0.00000001</distortionT1>
        <distortionT2>0.00000001</distortionT2>
        <CxPrime>0</CxPrime>
        <Cx>0</Cx>
        <Cy>0</Cy>
        <focalLength>0</focalLength>
        <hackBaseline>0</hackBaseline>
      </plugin>
    </sensor>
  </gazebo>
  <!-- Lidar -->
  <gazebo reference="laser">
    <sensor name="head_hokuyo_sensor" type="ray">
      <pose>0 0 0 0 0 0</pose>
      <visualize>false</visualize>
      <update_rate>40</update_rate>
      <ray>
        <scan>
          <horizontal>
            <samples>2000</samples>
            <resolution>1</resolution>
            <min_angle>-3.14159</min_angle>
            <max_angle>3.14159</max_angle>
          </horizontal>
        </scan>
        <range>
          <min>0.10</min>
          <max>30.0</max>
          <resolution>0.01</resolution>
        </range>
        <noise>
          <type>gaussian</type>
          <!-- Noise parameters based on published spec for Hokuyo laser
               achieving "+-30mm" accuracy at range < 10m.  A mean of 0.0m and
               stddev of 0.01m will put 99.7% of samples within 0.03m of the true
               reading. -->
          <mean>0.0</mean>
          <stddev>0.01</stddev>
        </noise>
      </ray>
      <plugin filename="libgazebo_ros_laser.so" name="gazebo_ros_head_hokuyo_controller">
        <topicName>/scan</topicName>
        <frameName>laser</frameName>
      </plugin>
    </sensor>
  </gazebo>
  <!-- imu sensor  -->
  <gazebo reference="imu_link">
    <gravity>true</gravity>
    <sensor name="imu_sensor" type="imu">
      <always_on>true</always_on>
      <update_rate>100</update_rate>
      <visualize>true</visualize>
      <topic>__default_topic__</topic>
      <plugin filename="libgazebo_ros_imu_sensor.so" name="imu_plugin">
        <topicName>imu</topicName>
        <bodyName>imu_link</bodyName>
        <updateRateHZ>10.0</updateRateHZ>
        <gaussianNoise>0.0</gaussianNoise>
        <xyzOffset>0 0 0</xyzOffset>
        <rpyOffset>0 0 0</rpyOffset>
        <frameName>imu0</frameName>
        <initialOrientationAsReference>false</initialOrientationAsReference>
      </plugin>
      <pose>0 0 0 0 0 0</pose>
    </sensor>
  </gazebo>
  <!-- ir sensor -->
  <gazebo reference="base_ir_back">
    <sensor name="TeraRanger2" type="ray">
      <pose>0 0 0 0 0 0</pose>
      <visualize>true</visualize>
      <update_rate>50</update_rate>
      <ray>
        <scan>
          <horizontal>
            <samples>10</samples>
            <resolution>1</resolution>
            <min_angle>-0.14835</min_angle>
            <max_angle>0.14835</max_angle>
          </horizontal>
          <vertical>
            <samples>10</samples>
            <resolution>1</resolution>
            <min_angle>-0.14835</min_angle>
            <max_angle>0.14835</max_angle>
          </vertical>
        </scan>
        <range>
          <min>0.01</min>
          <max>2</max>
          <resolution>0.02</resolution>
        </range>
      </ray>
      <plugin filename="libgazebo_ros_range.so" name="gazebo_ros_range">
        <gaussianNoise>0.005</gaussianNoise>
        <alwaysOn>true</alwaysOn>
        <updateRate>50</updateRate>
        <topicName>sensor/ir_back</topicName>
        <frameName>base_ir_back</frameName>
        <radiation>INFRARED</radiation>
        <fov>0.2967</fov>
      </plugin>
    </sensor>
  </gazebo>
  <material name="blue">
    <color rgba="0.1 0.1 0.9 1"/>
  </material>
  <material name="white">
    <color rgba="1 1 1 1"/>
  </material>
  <material name="green">
    <color rgba="0 1 0 1"/>
  </material>
  <material name="black">
    <color rgba="0 0 0 1"/>
  </material>
  <!-- ======================================= BASE LINK ======================================= -->
  <link name="base_link">
    <visual>
      <geometry>
        <mesh filename="package://miarobot_description/meshes/miarobot_colored.dae"/>
      </geometry>
      <material name="blue"/>
      <origin rpy="0 0 0" xyz="0 0 0"/>
    </visual>
    <collision>
      <geometry>
        <mesh filename="package://miarobot_description/meshes/miarobot.dae"/>
      </geometry>
      <origin rpy="0 0 0" xyz="0 0 0"/>
    </collision>
    <inertial>
      <mass value="5"/>
      <inertia ixx="10" ixy="0.0" ixz="0.0" iyy="10" iyz="0.0" izz="10"/>
    </inertial>
  </link>
  <!-- ======================================== WHEELS AND JOINTS ========================================= -->
  <link name="wheel_left_front">
    <!-- <visual>
                <geometry>
                    <cylinder length="0.035" radius="0.04"/>
                </geometry>
                <material name="black"/>
            </visual> -->
    <inertial>
      <origin xyz="0 0 0"/>
      <mass value="0.2"/>
      <inertia ixx="1.0" ixy="0.0" ixz="0.0" iyy="1.0" iyz="0.0" izz="1.0"/>
    </inertial>
    <collision>
      <geometry>
        <cylinder length="0.035" radius="0.04"/>
      </geometry>
      <surface>
        <friction>
          <ode>
            <mu>0.01</mu>
          </ode>
        </friction>
      </surface>
    </collision>
  </link>
  <joint name="left_front" type="continuous">
    <parent link="base_link"/>
    <child link="wheel_left_front"/>
    <origin rpy="1.5708 0 0" xyz="0.15 0.15 0.04"/>
    <axis xyz="0 0 -1"/>
  </joint>
  <link name="wheel_left_back">
    <!-- <visual>
                <geometry>
                    <cylinder length="0.035" radius="0.04"/>
                </geometry>
                <material name="black"/>
            </visual> -->
    <inertial>
      <origin xyz="0 0 0"/>
      <mass value="0.2"/>
      <inertia ixx="1.0" ixy="0.0" ixz="0.0" iyy="1.0" iyz="0.0" izz="1.0"/>
    </inertial>
    <collision>
      <geometry>
        <cylinder length="0.035" radius="0.04"/>
      </geometry>
      <surface>
        <friction>
          <ode>
            <mu>0.01</mu>
          </ode>
        </friction>
      </surface>
    </collision>
  </link>
  <joint name="left_back" type="continuous">
    <parent link="base_link"/>
    <child link="wheel_left_back"/>
    <origin rpy="1.5708 0 0" xyz="-0.15 0.15 0.04"/>
    <axis xyz="0 0 -1"/>
  </joint>
  <link name="wheel_right_front">
    <!-- <visual>
                <geometry>
                    <cylinder length="0.035" radius="0.04"/>
                </geometry>
                <material name="black"/>
            </visual> -->
    <inertial>
      <origin xyz="0 0 0"/>
      <mass value="0.2"/>
      <inertia ixx="1.0" ixy="0.0" ixz="0.0" iyy="1.0" iyz="0.0" izz="1.0"/>
    </inertial>
    <collision>
      <geometry>
        <cylinder length="0.035" radius="0.04"/>
      </geometry>
      <surface>
        <friction>
          <ode>
            <mu>0.01</mu>
          </ode>
        </friction>
      </surface>
    </collision>
  </link>
  <joint name="right_front" type="continuous">
    <parent link="base_link"/>
    <child link="wheel_right_front"/>
    <origin rpy="1.5708 0 0" xyz="0.15 -0.15 0.04"/>
    <axis xyz="0 0 -1"/>
  </joint>
  <link name="wheel_right_back">
    <!-- <visual>
                <geometry>
                    <cylinder length="0.035" radius="0.04"/>
                </geometry>
                <material name="black"/>
            </visual> -->
    <inertial>
      <origin xyz="0 0 0"/>
      <mass value="0.2"/>
      <inertia ixx="1.0" ixy="0.0" ixz="0.0" iyy="1.0" iyz="0.0" izz="1.0"/>
    </inertial>
    <collision>
      <geometry>
        <cylinder length="0.035" radius="0.04"/>
      </geometry>
      <surface>
        <friction>
          <ode>
            <mu>0.01</mu>
          </ode>
        </friction>
      </surface>
    </collision>
  </link>
  <joint name="right_back" type="continuous">
    <parent link="base_link"/>
    <child link="wheel_right_back"/>
    <origin rpy="1.5708 0 0" xyz="-0.15 -0.15 0.04"/>
    <axis xyz="0 0 -1"/>
  </joint>
  <!-- Kinect Camera -->
  <link name="kinect_camera_link">
    <collision>
      <origin rpy="0 0 0" xyz="0 0 0"/>
      <geometry>
        <box size="0.04 0.25 0.03"/>
      </geometry>
    </collision>
    <!-- <visual>
      <origin xyz="0 0 0" rpy="0 0 0"/>
      <geometry>
        <box size="${kinectWidth} ${kinectLength}  ${kinectHeight}"/>
      </geometry>
      <material name="green"/>
    </visual> -->
    <inertial>
      <mass value="0.25"/>
      <origin rpy="0 0 0" xyz="0 0 0"/>
      <box_inertia m="0.25" x="{kinectLength}" y="0.04" z="0.03"/>
      <inertia ixx="1e-6" ixy="0" ixz="0" iyy="1e-6" iyz="0" izz="1e-6"/>
    </inertial>
  </link>
  <joint name="kinect_camera_joint" type="fixed">
    <axis xyz="0 0 0"/>
    <origin rpy="0 0 0" xyz="0.16 0 0.185"/>
    <parent link="base_link"/>
    <child link="kinect_camera_link"/>
  </joint>
  <!-- LIDAR -->
  <link name="laser">
    <collision>
      <origin rpy="0 0 0" xyz="0 0 0.26"/>
      <geometry>
        <box size="0.1 0.1 0.1"/>
      </geometry>
    </collision>
    <inertial>
      <mass value="1e-5"/>
      <origin rpy="0 0 0" xyz="0 0 0"/>
      <inertia ixx="1e-6" ixy="0" ixz="0" iyy="1e-6" iyz="0" izz="1e-6"/>
    </inertial>
  </link>
  <joint name="hokuyo_joint" type="fixed">
    <axis xyz="0 1 0"/>
    <origin rpy="0 0 0" xyz="0 0 0.26"/>
    <parent link="base_link"/>
    <child link="laser"/>
  </joint>
  <!-- IMU Sensor -->
  <link name="imu_link">
    <!-- <collision>
      <origin xyz="0 0 0" rpy="0 0 0"/>
      <geometry>
        <box size="0.001 0.001 0.001"/>
      </geometry>
    </collision> -->
    <visual>
      <origin rpy="0 0 0" xyz="0 0 0"/>
      <geometry>
        <box size="0.001 0.001 0.001"/>
      </geometry>
    </visual>
    <inertial>
      <mass value="1e-5"/>
      <origin rpy="0 0 0" xyz="0 0 0"/>
      <inertia ixx="1e-6" ixy="0" ixz="0" iyy="1e-6" iyz="0" izz="1e-6"/>
    </inertial>
  </link>
  <joint name="imu_joint" type="fixed">
    <axis xyz="0 1 0"/>
    <origin rpy="0 0 0" xyz="0 0 0.18"/>
    <parent link="base_link"/>
    <child link="imu_link"/>
  </joint>
  <link name="base_ir_back">
    <collision>
      <origin rpy="0 0 0" xyz="0 0 0"/>
      <geometry>
        <box size="0.01 0.01 0.01"/>
      </geometry>
    </collision>
    <visual>
      <origin rpy="0 0 0" xyz="0 0 0"/>
      <geometry>
        <box size="0.01 0.01 0.01"/>
      </geometry>
    </visual>
    <inertial>
      <mass value="1e-5"/>
      <origin rpy="0 0 0" xyz="0 0 0"/>
      <inertia ixx="1e-6" ixy="0" ixz="0" iyy="1e-6" iyz="0" izz="1e-6"/>
    </inertial>
  </link>
  <joint name="ir_back_joint" type="fixed">
    <axis xyz="0 1 0"/>
    <origin rpy="0 0 0" xyz="0 0 0.26"/>
    <parent link="base_link"/>
    <child link="base_ir_back"/>
  </joint>
</robot>
